Workbook
Name CAJA_DE_CAPTACION: #REF!
Name LIN_DISTR_ELECT.: '[1]PRES 1'!#REF!
Name SUBEST_ELECTR: '[1]PRES 1'!#REF!

Sheet DATOS
C1: ESTUDIO FINANCIERO
C3: DATOS ADICIONALES
C5: Inflación | D5: 0.09 | E5: Anual
C6: Incremento salarial | D6: 0.12 | E6: Anual
C7: Incremento volumen | D7: 0.03 | E7: cada 3 meses durante el primer año
C8: Incremento precio unitario de venta | D8: 0.09 | E8: A partir del segundo semestre del primer año y durante los sig años
C10: Depreciación en línea recta | E10: LISR
C12: Amortización de la deuda de acuerdo a la
C13: dependencia que otorgará el financiamiento

Sheet CRONOGRAMA DE ACTIVIDADES
A1: CRONOGRAMA DE ACTIVIDADES
A3: PROYECTO:
A4: SOCIEDAD
A5: BENEFICIARIOS:
A7: CRONOGRAMA DE ACTIVIDADES
C8: MES
A9: CONCEPTO | C9: 1 | D9: 2 | E9: 3 | F9: 4 | G9: 5 | H9: 6 | I9: 7 | J9: 8 | K9: 9 | L9: 10 | M9: 11 | N9: 12
A51: CRONOGRAMA DE ACTIVIDADES SEGUNDO AÑO
B53: CONCEPTO | C53: 1 | D53: 2 | E53: 3 | F53: 4 | G53: 5 | H53: 6 | I53: 7 | J53: 8 | K53: 9 | L53: 10 | M53: 11 | N53: 12
A68: CRONOGRAMA DE ACTIVIDADES TERCER AÑO
B70: CONCEPTO | C70: 1 | D70: 2 | E70: 3 | F70: 4 | G70: 5 | H70: 6 | I70: 7 | J70: 8 | K70: 9 | L70: 10 | M70: 11 | N70: 12
A85: CRONOGRAMA DE ACTIVIDADES CUARTO AÑO
B87: CONCEPTO | C87: 1 | D87: 2 | E87: 3 | F87: 4 | G87: 5 | H87: 6 | I87: 7 | J87: 8 | K87: 9 | L87: 10 | M87: 11 | N87: 12

Sheet ESTRUCTURA FINANCIERA
A1: ESTUDIO FINANCIERO
A3: ESTRUCTURA FINANCIERA
A5: PROYECTO: Las Amarguitas Fabrica de Cervezas y Destilados
A6: SOCIEDAD RESPONSABILIDAD LIMITADA
A7: BENEFICIARIOS: PABLO PUIG TRESS, HUGO PUIG TRESS.
A9: DESGLOSE DE INVERSION PARA UN AÑO
A10: CONCEPTO | B10: UNIDAD DE | C10: CANTIDAD | D10: PRECIO | E10: COSTO | F10: APORTACION | J10: Monto total | K10: $ SE | L10: % | M10: $ GRUPO | N10: % | O10: TOTAL
B11: MEDIDA | D11: UNITARIO | E11: TOTAL | F11: DEPENDENCIA | G11: GRUPO | I11: Capital de Trabajo | J11: 28600 | K11: 0 | L11: 0 | M11: =J11 -> 28600 | N11: 1 | O11: 1
A12: CAPITAL DE TRABAJO | I12: Inversión fija | J12: 759000 | K12: 759000 | L12: 1 | N12: 0 | O12: 1
A13: MALTA BASE | B13: KG | C13: 120 | D13: =E13/C13 -> 50 | E13: 6000 | F13: 0 | G13: =E13 -> 6000 | I13: Inversión diferida | J13: 40000 | K13: 40000 | L13: 1 | N13: 0 | O13: 1
A14: MALTAS ESPECIALES | B14: KG | C14: 10 | D14: =E14/C14 -> 60 | E14: 600 | F14: 0 | G14: =E14 -> 600
A15: LUPULO | B15: KG | C15: 2 | D15: =E15/C15 -> 800 | E15: 1600 | F15: 0 | G15: =E15 -> 1600 | K15: =SUM(K11:K13) -> 799000 | M15: =SUM(M11:M13) -> 28600
A16: LEVADURA | B16: KG | C16: 1 | D16: =E16/C16 -> 5000 | E16: 5000 | F16: 0 | G16: =E16 -> 5000
A17: AGUA | B17: LITROS | C17: 500 | D17: =E17/C17 -> 5 | E17: 2500 | F17: 0 | G17: =E17 -> 2500
A18: ENVASES | B18: PZ | C18: 1000 | D18: =E18/C18 -> 12.5 | E18: 12500 | F18: 0 | G18: =E18 -> 12500
A19: CLARIFICANTE | B19: KG | C19: 1 | D19: =E19/C19 -> 400 | E19: 400 | F19: 0 | G19: =E19 -> 400
A21: INVERSION FIJA
A22: Plataforma y Escalera de Operación | B22: Pz | C22: 1 | D22: 50000 | E22: =D22*C22 -> 50000 | F22: =E22 -> 50000 | G22: 0
A23: Mash Tun | B23: Pz | C23: 1 | D23: 169000 | E23: =D23*C23 -> 169000 | F23: =E23 -> 169000 | G23: 0
A24: Lauter Tun | B24: Pz | C24: 1 | D24: 220000 | E24: =D24*C24 -> 220000 | F24: =E24 -> 220000 | G24: 0
A25: Kettle | B25: Pz | C25: 1 | D25: 50000 | E25: =D25*C25 -> 50000 | F25: =E25 -> 50000 | G25: 0
A26: Tanque con Agitador | B26: Pz | C26: 1 | D26: 125000 | E26: =D26*C26 -> 125000 | F26: =E26 -> 125000 | G26: 0
A27: Tanque de Agua | B27: Pz | C27: 1 | D27: 95000 | E27: =D27*C27 -> 95000 | F27: =E27 -> 95000 | G27: 0
A28: Intercambiador de Calor | B28: Pz | C28: 1 | D28: 30000 | E28: =D28*C28 -> 30000 | F28: =E28 -> 30000 | G28: 0
A29: Sistema de Tuberías y Bomba Sanitaria | B29: Pz | C29: 1 | D29: 20000 | E29: =D29*C29 -> 20000 | F29: =E29 -> 20000 | G29: 0
A30: Subtotal | E30: =SUM(E12:E29) -> 787600 | F30: =SUM(F22:F29) -> 759000 | G30: =SUM(G13:G28) -> 28600
A31: INVERSION DIFERIDA
A34: CAPACITACIÓN | B34: servicio | C34: 1 | D34: 40000 | E34: 40000 | F34: 40000 | G34: 0
A36: TOTAL | E36: =E34+E30 -> 827600 | F36: =F34+F30 -> 799000 | G36: =+G34+G30 -> 28600
A37: PORCENTAJE | E37: =+E36/E36 -> 1 | F37: =+F36/E36 -> 0.96544224 | G37: =G36/E36 -> 0.034557757
A42: NOTAS:

Sheet CUADRO DE EGRESOS E INGRESOS
A1: ESTRUCTURA DE INGRESOS Y EGERESOS
A3: SITUACION FINANCIERA ACTUAL Y PROYECTADA
A5: PROYECTO:
A6: SOCIEDAD
A7: BENEFICIARIOS:
B9: FLUJO DE I N G R E S O S Y E G R E S O S
A10: PRIMER AÑO DE INVERSIÓN
A11: C O N C E P T O | C11: 1 MES | D11: 2 MES | E11: 3 MES | F11: 4 MES | G11: 5 MES | H11: 6 MES | I11: 7 MES | J11: 8 MES | K11: 9 MES | L11: 10 MES | M11: 11 MES | N11: 12 MES | O11: TOTAL
A12: TOTAL DE INGRESOS | Q12: CALCULO DE UTILIDADES
A13: VENTAS | C13: =INGRESOS!B17 -> 291523.05 | D13: =INGRESOS!C17 -> 291523.05 | E13: =INGRESOS!D17 -> 291523.05 | F13: =INGRESOS!E17 -> 291523.05 | G13: =INGRESOS!F17 -> 291523.05 | H13: =INGRESOS!G17 -> 291523.05 | I13: =INGRESOS!H17 -> 317760.12 | J13: =INGRESOS!I17 -> 317760.12 | ... N13: =INGRESOS!M17 -> 317760.12 | O13: =SUM(C13:N13) -> 3655699 | Q13: =O13-O18 -> 1521321.2
A14: TOTAL DE EGRESOS | Q14: =Q13-25000 -> 1496321.2
A15: VARIABLE | C15: =COSTOS!B29 -> 144198.13 | D15: =COSTOS!C29 -> 144198.13 | E15: =COSTOS!D29 -> 144198.13 | F15: =COSTOS!E29 -> 144198.13 | G15: =COSTOS!F29 -> 144198.13 | H15: =COSTOS!G29 -> 144198.13 | I15: =COSTOS!H29 -> 144198.13 | J15: =COSTOS!I29 -> 144198.13 | ... N15: =COSTOS!M29 -> 144198.13 | O15: =SUM(C15:N15) -> 1730377.5 | Q15: =Q14*0.1 -> 149632.12
A16: FIJOS | C16: =COSTOS!B33 -> 33666.693 | D16: =COSTOS!C33 -> 33666.693 | E16: =COSTOS!D33 -> 33666.693 | F16: =COSTOS!E33 -> 33666.693 | G16: =COSTOS!F33 -> 33666.693 | H16: =COSTOS!G33 -> 33666.693 | I16: =COSTOS!H33 -> 33666.693 | J16: =COSTOS!I33 -> 33666.693 | ... N16: =COSTOS!M33 -> 33666.693 | O16: =SUM(C16:N16) -> 404000.32 | Q16: =Q14*0.3 -> 448896.37
A17: SALDO | C17: =SUM(C15:C16) -> 177864.82 | D17: =SUM(D15:D16) -> 177864.82 | E17: =SUM(E15:E16) -> 177864.82 | F17: =SUM(F15:F16) -> 177864.82 | G17: =SUM(G15:G16) -> 177864.82 | H17: =SUM(H15:H16) -> 177864.82 | I17: =SUM(I15:I16) -> 177864.82 | J17: =SUM(J15:J16) -> 177864.82 | ... N17: =SUM(N15:N16) -> 177864.82 | O17: =SUM(C17:N17) -> 2134377.8 | Q17: =Q15+Q16 -> 598528.49
A18: SALDO ACUMULADO | C18: =+C17 -> 177864.82 | D18: =+D17+C18 -> 355729.64 | E18: =+E17+D18 -> 533594.46 | F18: =+F17+E18 -> 711459.27 | G18: =+G17+F18 -> 889324.09 | H18: =+H17+G18 -> 1067188.9 | I18: =+I17+H18 -> 1245053.7 | J18: =+J17+I18 -> 1422918.5 | K18: =+K17+J18 -> 1600783.4 | ... N18: =+N17+M18 -> 2134377.8 | O18: =+N18 -> 2134377.8 | Q18: =Q14-Q17 -> 897792.73
A22: PROYECCION FINANCIERA ANUAL
A24: SEGUNDO AÑO DE INVERSIÓN
A25: C O N C E P T O | C25: 1 MES | D25: 2 MES | E25: 3 MES | F25: 4 MES | G25: 5 MES | H25: 6 MES | I25: 7 MES | J25: 8 MES | K25: 9 MES | L25: 10 MES | M25: 11 MES | N25: 12 MES | O25: TOTAL
A26: TOTAL DE INGRESOS | Q26: CALCULO DE UTILIDADES
A27: VENTAS | C27: =INGRESOS!B29 -> 346358.54 | D27: =INGRESOS!C29 -> 346358.54 | E27: =INGRESOS!D29 -> 346358.54 | F27: =INGRESOS!E29 -> 346358.54 | G27: =INGRESOS!F29 -> 346358.54 | H27: =INGRESOS!G29 -> 346358.54 | I27: =INGRESOS!H29 -> 346358.54 | J27: =INGRESOS!I29 -> 346358.54 | ... N27: =INGRESOS!M29 -> 346358.54 | O27: =SUM(C27:N27) -> 4156302.4 | Q27: =O27-O32 -> 2008399.8
A28: EGRESOS | Q28: =Q27-25000 -> 1983399.8
A29: VARIABLE | C29: =COSTOS!B44 -> 145154.69 | D29: =COSTOS!C44 -> 145154.69 | E29: =COSTOS!D44 -> 145154.69 | F29: =COSTOS!E44 -> 145154.69 | G29: =COSTOS!F44 -> 145154.69 | H29: =COSTOS!G44 -> 145154.69 | I29: =COSTOS!H44 -> 145154.69 | J29: =COSTOS!I44 -> 145154.69 | ... N29: =COSTOS!M44 -> 145154.69 | O29: =SUM(C29:N29) -> 1741856.3 | Q29: =Q28*0.1 -> 198339.98
A30: FIJOS | C30: =COSTOS!B48 -> 33837.194 | D30: =COSTOS!C48 -> 33837.194 | E30: =COSTOS!D48 -> 33837.194 | F30: =COSTOS!E48 -> 33837.194 | G30: =COSTOS!F48 -> 33837.194 | H30: =COSTOS!G48 -> 33837.194 | I30: =COSTOS!H48 -> 33837.194 | J30: =COSTOS!I48 -> 33837.194 | ... N30: =COSTOS!M48 -> 33837.194 | O30: =SUM(C30:N30) -> 406046.32 | Q30: =Q28*0.3 -> 595019.95
A31: SALDO | C31: =C29+C30 -> 178991.88 | D31: =D29+D30 -> 178991.88 | E31: =E29+E30 -> 178991.88 | F31: =F29+F30 -> 178991.88 | G31: =G29+G30 -> 178991.88 | H31: =H29+H30 -> 178991.88 | I31: =I29+I30 -> 178991.88 | J31: =J29+J30 -> 178991.88 | ... N31: =N29+N30 -> 178991.88 | O31: =SUM(C31:N31) -> 2147902.6 | Q31: =Q29+Q30 -> 793359.94
A32: SALDO ACUMULADO | C32: =+C31 -> 178991.88 | D32: =+D31+C32 -> 357983.76 | E32: =+E31+D32 -> 536975.65 | F32: =+F31+E32 -> 715967.53 | G32: =+G31+F32 -> 894959.41 | H32: =+H31+G32 -> 1073951.3 | I32: =+I31+H32 -> 1252943.2 | J32: =+J31+I32 -> 1431935.1 | K32: =+K31+J32 -> 1610926.9 | ... N32: =+N31+M32 -> 2147902.6 | O32: =+N32 -> 2147902.6 | Q32: =Q28-Q31 -> 1190039.9
A37: TERCER AÑO DE INVERSIÓN
A38: C O N C E P T O | C38: 1 MES | D38: 2 MES | E38: 3 MES | F38: 4 MES | G38: 5 MES | H38: 6 MES | I38: 7 MES | J38: 8 MES | K38: 9 MES | L38: 10 MES | M38: 11 MES | N38: 12 MES | O38: TOTAL
A39: TOTAL DE INGRESOS | Q39: CALCULO DE UTILIDADES
A40: VENTAS | C40: =INGRESOS!B41 -> 377530.8 | D40: =INGRESOS!C41 -> 377530.8 | E40: =INGRESOS!D41 -> 377530.8 | F40: =INGRESOS!E41 -> 377530.8 | G40: =INGRESOS!F41 -> 377530.8 | H40: =INGRESOS!G41 -> 377530.8 | I40: =INGRESOS!H41 -> 377530.8 | J40: =INGRESOS!I41 -> 377530.8 | ... N40: =INGRESOS!M41 -> 377530.8 | O40: =SUM(C40:N40) -> 4530369.6 | Q40: =O40-O45 -> 2368830.7
A41: EGRESOS | Q41: =Q40-25000 -> 2343830.7
A42: VARIABLE | C42: =COSTOS!B57 -> 146118.84 | D42: =COSTOS!C57 -> 146118.84 | E42: =COSTOS!D57 -> 146118.84 | F42: =COSTOS!E57 -> 146118.84 | G42: =COSTOS!F57 -> 146118.84 | H42: =COSTOS!G57 -> 146118.84 | I42: =COSTOS!H57 -> 146118.84 | J42: =COSTOS!I57 -> 146118.84 | ... N42: =COSTOS!M57 -> 146118.84 | O42: =SUM(C42:N42) -> 1753426.1 | Q42: =Q41*0.1 -> 234383.07
A43: FIJOS | C43: =COSTOS!B61 -> 34009.399 | D43: =COSTOS!C61 -> 34009.399 | E43: =COSTOS!D61 -> 34009.399 | F43: =COSTOS!E61 -> 34009.399 | G43: =COSTOS!F61 -> 34009.399 | H43: =COSTOS!G61 -> 34009.399 | I43: =COSTOS!H61 -> 34009.399 | J43: =COSTOS!I61 -> 34009.399 | ... N43: =COSTOS!M61 -> 34009.399 | O43: =SUM(C43:N43) -> 408112.79 | Q43: =Q41*0.3 -> 703149.22
A44: SALDO | C44: =C42+C43 -> 180128.24 | D44: =D42+D43 -> 180128.24 | E44: =E42+E43 -> 180128.24 | F44: =F42+F43 -> 180128.24 | G44: =G42+G43 -> 180128.24 | H44: =H42+H43 -> 180128.24 | I44: =I42+I43 -> 180128.24 | J44: =J42+J43 -> 180128.24 | ... N44: =N42+N43 -> 180128.24 | O44: =SUM(C44:N44) -> 2161538.9 | Q44: =Q42+Q43 -> 937532.29
A45: SALDO ACUMULADO | C45: =+C44 -> 180128.24 | D45: =+D44+C45 -> 360256.49 | E45: =+E44+D45 -> 540384.73 | F45: =+F44+E45 -> 720512.97 | G45: =+G44+F45 -> 900641.21 | H45: =+H44+G45 -> 1080769.5 | I45: =+I44+H45 -> 1260897.7 | J45: =+J44+I45 -> 1441025.9 | K45: =+K44+J45 -> 1621154.2 | ... N45: =+N44+M45 -> 2161538.9 | O45: =+N45 -> 2161538.9 | Q45: =Q41-Q44 -> 1406298.4
A48: CUARTO AÑO DE INVERSIÓN
A49: C O N C E P T O | C49: 1 MES | D49: 2 MES | E49: 3 MES | F49: 4 MES | G49: 5 MES | H49: 6 MES | I49: 7 MES | J49: 8 MES | K49: 9 MES | L49: 10 MES | M49: 11 MES | N49: 12 MES | O49: TOTAL
A50: TOTAL DE INGRESOS | Q50: CALCULO DE UTILIDADES
A51: VENTAS | C51: =INGRESOS!B53 -> 411508.58 | D51: =INGRESOS!C53 -> 411508.58 | E51: =INGRESOS!D53 -> 411508.58 | F51: =INGRESOS!E53 -> 411508.58 | G51: =INGRESOS!F53 -> 411508.58 | H51: =INGRESOS!G53 -> 411508.58 | I51: =INGRESOS!H53 -> 411508.58 | J51: =INGRESOS!I53 -> 411508.58 | ... N51: =INGRESOS!M53 -> 411508.58 | O51: =SUM(C51:N51) -> 4938102.9 | Q51: =O51-O56 -> 2764902.3
A52: EGRESOS | Q52: =Q51-25000 -> 2739902.3
A53: VARIABLE | C53: =COSTOS!B70 -> 147090.65 | D53: =COSTOS!C70 -> 147090.65 | E53: =COSTOS!D70 -> 147090.65 | F53: =COSTOS!E70 -> 147090.65 | G53: =COSTOS!F70 -> 147090.65 | H53: =COSTOS!G70 -> 147090.65 | I53: =COSTOS!H70 -> 147090.65 | J53: =COSTOS!I70 -> 147090.65 | ... N53: =COSTOS!M70 -> 147090.65 | O53: =SUM(C53:N53) -> 1765087.8 | Q53: =Q52*0.1 -> 273990.23
...

Sheet COSTOS
B2: COSTOS DE PRODUCCION AÑO 1 sin inversión
A3: VARIABLES | B3: 1 | C3: 2 | D3: 3 | E3: 4 | F3: 5 | G3: 6 | H3: 7 | I3: 8 | J3: 9 | K3: 10 | L3: 11 | M3: 12 | N3: TOTAL
A4: TOTAL VARIABLES | B4: =SUM(B5:B7) -> 91844.451 | C4: =SUM(C5:C7) -> 91844.451 | D4: =SUM(D5:D7) -> 91844.451 | E4: =SUM(E5:E7) -> 91844.451 | F4: =SUM(F5:F7) -> 91844.451 | G4: =SUM(G5:G7) -> 91844.451 | H4: =SUM(H5:H7) -> 91844.451 | I4: =SUM(I5:I7) -> 91844.451 | ... N4: =SUM(N5:N7) -> 1102133.4
A5: Materia prima | B5: ='M. DE CALCULO DE COSTOS VARIABL'!$G$26 -> 52882.5 | C5: ='M. DE CALCULO DE COSTOS VARIABL'!$G$26 -> 52882.5 | D5: ='M. DE CALCULO DE COSTOS VARIABL'!$G$26 -> 52882.5 | E5: ='M. DE CALCULO DE COSTOS VARIABL'!$G$26 -> 52882.5 | F5: ='M. DE CALCULO DE COSTOS VARIABL'!$G$26 -> 52882.5 | G5: ='M. DE CALCULO DE COSTOS VARIABL'!$G$26 -> 52882.5 | H5: ='M. DE CALCULO DE COSTOS VARIABL'!$G$26 -> 52882.5 | I5: ='M. DE CALCULO DE COSTOS VARIABL'!$G$26 -> 52882.5 | ... M5: ='M. DE CALCULO DE COSTOS VARIABL'!$G$26 -> 52882.5 | N5: =SUM(B5:M5) -> 634590
A6: Mano de obra directa | B6: ='M. DE CALCULO DE COSTOS VARIABL'!$D$27 -> 16729.14 | C6: ='M. DE CALCULO DE COSTOS VARIABL'!$D$27 -> 16729.14 | D6: ='M. DE CALCULO DE COSTOS VARIABL'!$D$27 -> 16729.14 | E6: ='M. DE CALCULO DE COSTOS VARIABL'!$D$27 -> 16729.14 | F6: ='M. DE CALCULO DE COSTOS VARIABL'!$D$27 -> 16729.14 | G6: ='M. DE CALCULO DE COSTOS VARIABL'!$D$27 -> 16729.14 | H6: ='M. DE CALCULO DE COSTOS VARIABL'!$D$27 -> 16729.14 | I6: ='M. DE CALCULO DE COSTOS VARIABL'!$D$27 -> 16729.14 | ... M6: ='M. DE CALCULO DE COSTOS VARIABL'!$D$27 -> 16729.14 | N6: =SUM(B6:M6) -> 200749.68
A7: Costos Indirectos de Fabricación | B7: ='M. DE CALCULO DE COSTOS VARIABL'!$E$42 -> 22232.811 | C7: ='M. DE CALCULO DE COSTOS VARIABL'!$E$42 -> 22232.811 | D7: ='M. DE CALCULO DE COSTOS VARIABL'!$E$42 -> 22232.811 | E7: ='M. DE CALCULO DE COSTOS VARIABL'!$E$42 -> 22232.811 | F7: ='M. DE CALCULO DE COSTOS VARIABL'!$E$42 -> 22232.811 | G7: ='M. DE CALCULO DE COSTOS VARIABL'!$E$42 -> 22232.811 | H7: ='M. DE CALCULO DE COSTOS VARIABL'!$E$42 -> 22232.811 | I7: ='M. DE CALCULO DE COSTOS VARIABL'!$E$42 -> 22232.811 | ... M7: ='M. DE CALCULO DE COSTOS VARIABL'!$E$42 -> 22232.811 | N7: =SUM(B7:M7) -> 266793.73
A8: TOTAL FIJOS | B8: =B9+B10 -> 33666.693 | C8: =SUM(C9:C10) -> 39716.726 | D8: =SUM(D9:D10) -> 33666.693 | E8: =SUM(E9:E10) -> 33666.693 | F8: =SUM(F9:F10) -> 33666.693 | G8: =SUM(G9:G10) -> 33666.693 | H8: =SUM(H9:H10) -> 33666.693 | I8: =SUM(I9:I10) -> 33666.693 | J8: =SUM(J9:J10) -> 33666.693 | ... M8: =SUM(M9:M10) -> 33666.693 | N8: =SUM(B8:M8) -> 410050.35
A9: Gastos de administración | B9: ='M. DE CALCULO DE GASTOS FIJOS'!F13 -> 17050.07 | C9: ='M. DE CALCULO DE GASTOS FIJOS'!G13 -> 17050.07 | D9: ='M. DE CALCULO DE GASTOS FIJOS'!H13 -> 17050.07 | E9: ='M. DE CALCULO DE GASTOS FIJOS'!I13 -> 17050.07 | F9: ='M. DE CALCULO DE GASTOS FIJOS'!J13 -> 17050.07 | G9: ='M. DE CALCULO DE GASTOS FIJOS'!K13 -> 17050.07 | H9: ='M. DE CALCULO DE GASTOS FIJOS'!L13 -> 17050.07 | I9: ='M. DE CALCULO DE GASTOS FIJOS'!M13 -> 17050.07 | ... M9: ='M. DE CALCULO DE GASTOS FIJOS'!Q13 -> 17050.07 | N9: =SUM(B9:M9) -> 204600.84
A10: Gastos de venta | B10: ='M. DE CALCULO DE GASTOS FIJOS'!F21 -> 16616.623 | C10: ='M. DE CALCULO DE GASTOS FIJOS'!G21 -> 22666.656 | D10: ='M. DE CALCULO DE GASTOS FIJOS'!H21 -> 16616.623 | E10: ='M. DE CALCULO DE GASTOS FIJOS'!I21 -> 16616.623 | F10: ='M. DE CALCULO DE GASTOS FIJOS'!J21 -> 16616.623 | G10: ='M. DE CALCULO DE GASTOS FIJOS'!K21 -> 16616.623 | H10: ='M. DE CALCULO DE GASTOS FIJOS'!L21 -> 16616.623 | I10: ='M. DE CALCULO DE GASTOS FIJOS'!M21 -> 16616.623 | ... M10: ='M. DE CALCULO DE GASTOS FIJOS'!Q21 -> 16616.623 | N10: =SUM(B10:M10) -> 205449.51
A11: TOTAL COSTO OPERACIÓN | B11: =+B8+B4 -> 125511.14 | C11: =+C8+C4 -> 131561.18 | D11: =+D8+D4 -> 125511.14 | E11: =+E8+E4 -> 125511.14 | F11: =+F8+F4 -> 125511.14 | G11: =+G8+G4 -> 125511.14 | H11: =+H8+H4 -> 125511.14 | I11: =+I8+I4 -> 125511.14 | ... N11: =+N8+N4 -> 1512183.8
B12: =B11/3000 -> 41.837048 | C12: =C11/3000 -> 43.853726 | D12: =D11/3000 -> 41.837048 | E12: =E11/3000 -> 41.837048 | F12: =F11/3000 -> 41.837048 | G12: =G11/3000 -> 41.837048 | H12: =H11/3000 -> 41.837048 | I12: =I11/3000 -> 41.837048 | ... M12: =M11/3000 -> 41.837048
J14: Antes de la inversión
A15: VARIABLES | B15: AÑO 0 | C15: AÑO 1 | D15: AÑO 2 | E15: AÑO3 | F15: AÑO 4 | G15: AÑO 5 | J15: Costos promedio por litro de cerveza | M15: =AVERAGE(B12:M12) -> 42.005104 | N15: =M15*1500 -> 63007.657 | P15: Costo promedio
A16: TOTAL VARIABLES | B16: =SUM(B17:B19) -> 1102133.4 | C16: =SUM(C17:C19) -> 1730377.5 | D16: {=N44:N51} -> 1741856.3 | E16: {=N57:N64} -> 1753426.1 | F16: {=N70:N77} -> 1765087.8 | G16: {=N83:N90} -> 1776842.1 | J16: Precio de venta | M16: 97.5 | N16: =M16*1500 -> 146250 | P16: 80
A17: Materia prima | B17: =N5 -> 634590 | C17: =N30 -> 1262834.1 | D17: 1272305.4 | E17: 1281847.6 | F17: 1291461.5 | G17: 1301147.5 | J17: Utilidad bruta por litro | M17: =M16-M15 -> 55.494896 | N17: =N16-N15 -> 83242.343 | P17: 90
A18: Mano de obra directa | B18: =N6 -> 200749.68 | C18: =N31 -> 200749.68 | D18: 202757.18 | E18: 204784.75 | F18: 206832.6 | G18: 208900.92 | J18: Después de la inversión | P18: 120
A19: Costos Indirectos de Fabricación | B19: =N7 -> 266793.73 | C19: =N32 -> 266793.73 | D19: 266793.73 | E19: 266793.73 | F19: 266793.73 | G19: 266793.73 | J19: Costos promedio por litro de cerveza | M19: =E41 -> 59.486561 | N19: =M19*2990 -> 177864.82 | P19: 100
A20: TOTAL FIJOS | B20: =N8 -> 410050.35 | C20: =N33 -> 404000.32 | D20: 406046.32 | E20: 408112.79 | F20: 410199.93 | G20: 412307.93 | J20: Precio de venta | M20: =97.5 -> 97.5 | N20: =M20*2990 -> 291525 | P20: =AVERAGE(P16:P19) -> 97.5
A21: Gastos de administración | B21: =N9 -> 204600.84 | C21: =N34 -> 204600.84 | D21: 206646.85 | E21: 208713.32 | F21: 210800.45 | G21: 212908.45 | J21: Utilidad bruta por litro | M21: =M20-M19 -> 38.013439 | N21: =N20-N19 -> 113660.18
A22: Gastos de venta | B22: =N10 -> 205449.51 | C22: =N35 -> 199399.48 | D22: 199399.48 | E22: 199399.48 | F22: 199399.48 | G22: 199399.48 | P22: Factor de aumento
A23: TOTAL COSTO OPERACIÓN | B23: =B16+B20 -> 1512183.8 | C23: =C16+C20 -> 2134377.8 | D23: 2147902.6 | E23: 2161538.9 | F23: 2175287.8 | G23: 2189150 | P23: 1.99
B27: COSTOS DE PRODUCCION AÑO 1
A28: VARIABLES | B28: 1 | C28: 2 | D28: 3 | E28: 4 | F28: 5 | G28: 6 | H28: 7 | I28: 8 | J28: 9 | K28: 10 | L28: 11 | M28: 12 | N28: TOTAL
A29: TOTAL VARIABLES | B29: =SUM(B30:B32) -> 144198.13 | C29: =SUM(C30:C32) -> 144198.13 | D29: =SUM(D30:D32) -> 144198.13 | E29: =SUM(E30:E32) -> 144198.13 | F29: =SUM(F30:F32) -> 144198.13 | G29: =SUM(G30:G32) -> 144198.13 | H29: =SUM(H30:H32) -> 144198.13 | I29: =SUM(I30:I32) -> 144198.13 | ... N29: =SUM(N30:N32) -> 1730377.5
A30: Materia prima | B30: ='M. DE CALCULO DE COSTOS VARIABL'!$G$26*$P$23 -> 105236.18 | C30: ='M. DE CALCULO DE COSTOS VARIABL'!$G$26*$P$23 -> 105236.18 | D30: ='M. DE CALCULO DE COSTOS VARIABL'!$G$26*$P$23 -> 105236.18 | E30: ='M. DE CALCULO DE COSTOS VARIABL'!$G$26*$P$23 -> 105236.18 | F30: ='M. DE CALCULO DE COSTOS VARIABL'!$G$26*$P$23 -> 105236.18 | G30: ='M. DE CALCULO DE COSTOS VARIABL'!$G$26*$P$23 -> 105236.18 | H30: ='M. DE CALCULO DE COSTOS VARIABL'!$G$26*$P$23 -> 105236.18 | I30: ='M. DE CALCULO DE COSTOS VARIABL'!$G$26*$P$23 -> 105236.18 | ... M30: ='M. DE CALCULO DE COSTOS VARIABL'!$G$26*$P$23 -> 105236.18 | N30: =SUM(B30:M30) -> 1262834.1
A31: Mano de obra directa | B31: =$B$6 -> 16729.14 | C31: =$B$6 -> 16729.14 | D31: =$B$6 -> 16729.14 | E31: =$B$6 -> 16729.14 | F31: =$B$6 -> 16729.14 | G31: =$B$6 -> 16729.14 | H31: =$B$6 -> 16729.14 | I31: =$B$6 -> 16729.14 | ... M31: =$B$6 -> 16729.14 | N31: =SUM(B31:M31) -> 200749.68
A32: Costos Indirectos de Fabricación | B32: ='M. DE CALCULO DE COSTOS VARIABL'!$F$42 -> 22232.811 | C32: ='M. DE CALCULO DE COSTOS VARIABL'!$F$42 -> 22232.811 | D32: ='M. DE CALCULO DE COSTOS VARIABL'!$F$42 -> 22232.811 | E32: ='M. DE CALCULO DE COSTOS VARIABL'!$F$42 -> 22232.811 | F32: ='M. DE CALCULO DE COSTOS VARIABL'!$F$42 -> 22232.811 | G32: ='M. DE CALCULO DE COSTOS VARIABL'!$F$42 -> 22232.811 | H32: ='M. DE CALCULO DE COSTOS VARIABL'!$F$42 -> 22232.811 | I32: ='M. DE CALCULO DE COSTOS VARIABL'!$F$42 -> 22232.811 | ... M32: ='M. DE CALCULO DE COSTOS VARIABL'!$F$42 -> 22232.811 | N32: =SUM(B32:M32) -> 266793.73
A33: TOTAL FIJOS | B33: =B34+B35 -> 33666.693 | C33: =SUM(C34:C35) -> 33666.693 | D33: =SUM(D34:D35) -> 33666.693 | E33: =SUM(E34:E35) -> 33666.693 | F33: =SUM(F34:F35) -> 33666.693 | G33: =SUM(G34:G35) -> 33666.693 | H33: =SUM(H34:H35) -> 33666.693 | I33: =SUM(I34:I35) -> 33666.693 | J33: =SUM(J34:J35) -> 33666.693 | ... M33: =SUM(M34:M35) -> 33666.693 | N33: =SUM(B33:M33) -> 404000.32
A34: Gastos de administración | B34: =$B$9 -> 17050.07 | C34: =$B$9 -> 17050.07 | D34: =$B$9 -> 17050.07 | E34: =$B$9 -> 17050.07 | F34: =$B$9 -> 17050.07 | G34: =$B$9 -> 17050.07 | H34: =$B$9 -> 17050.07 | I34: =$B$9 -> 17050.07 | ... M34: =$B$9 -> 17050.07 | N34: =SUM(B34:M34) -> 204600.84
A35: Gastos de venta | B35: =$B$10 -> 16616.623 | C35: =$B$10 -> 16616.623 | D35: =$B$10 -> 16616.623 | E35: =$B$10 -> 16616.623 | F35: =$B$10 -> 16616.623 | G35: =$B$10 -> 16616.623 | H35: =$B$10 -> 16616.623 | I35: =$B$10 -> 16616.623 | ... M35: =$B$10 -> 16616.623 | N35: =SUM(B35:M35) -> 199399.48
A36: TOTAL COSTO OPERACIÓN | B36: =+B33+B29 -> 177864.82 | C36: =+C33+C29 -> 177864.82 | D36: =+D33+D29 -> 177864.82 | E36: =+E33+E29 -> 177864.82 | F36: =+F33+F29 -> 177864.82 | G36: =+G33+G29 -> 177864.82 | H36: =+H33+H29 -> 177864.82 | I36: =+I33+I29 -> 177864.82 | ... N36: =+N33+N29 -> 2134377.8
B38: =B36/2990 -> 59.486561 | C38: =C36/2990 -> 59.486561 | D38: =D36/2990 -> 59.486561 | E38: =E36/2990 -> 59.486561 | F38: =F36/2990 -> 59.486561 | G38: =G36/2990 -> 59.486561 | H38: =H36/2990 -> 59.486561 | I38: =I36/2990 -> 59.486561 | ... M38: =M36/2990 -> 59.486561
E41: =AVERAGE(B38:M38) -> 59.486561
B42: COSTOS DE PRODUCCION AÑO 2
A43: VARIABLES | B43: 1 | C43: 2 | D43: 3 | E43: 4 | F43: 5 | G43: 6 | H43: 7 | I43: 8 | J43: 9 | K43: 10 | L43: 11 | M43: 12 | N43: TOTAL
A44: TOTAL VARIABLES | B44: =SUM(B45:B47) -> 145154.69 | C44: =SUM(C45:C47) -> 145154.69 | D44: =SUM(D45:D47) -> 145154.69 | E44: =SUM(E45:E47) -> 145154.69 | F44: =SUM(F45:F47) -> 145154.69 | G44: =SUM(G45:G47) -> 145154.69 | H44: =SUM(H45:H47) -> 145154.69 | I44: =SUM(I45:I47) -> 145154.69 | ... N44: =SUM(N45:N47) -> 1741856.3
A45: Materia prima | B45: =$B$30*1.0075 -> 106025.45 | C45: =$B$30*1.0075 -> 106025.45 | D45: =$B$30*1.0075 -> 106025.45 | E45: =$B$30*1.0075 -> 106025.45 | F45: =$B$30*1.0075 -> 106025.45 | G45: =$B$30*1.0075 -> 106025.45 | H45: =$B$30*1.0075 -> 106025.45 | I45: =$B$30*1.0075 -> 106025.45 | ... M45: =$B$30*1.0075 -> 106025.45 | N45: =SUM(B45:M45) -> 1272305.4
A46: Mano de obra directa | B46: =$B$6*1.01 -> 16896.431 | C46: =$B$6*1.01 -> 16896.431 | D46: =$B$6*1.01 -> 16896.431 | E46: =$B$6*1.01 -> 16896.431 | F46: =$B$6*1.01 -> 16896.431 | G46: =$B$6*1.01 -> 16896.431 | H46: =$B$6*1.01 -> 16896.431 | I46: =$B$6*1.01 -> 16896.431 | ... M46: =$B$6*1.01 -> 16896.431 | N46: =SUM(B46:M46) -> 202757.18
A47: Costos Indirectos de Fabricación | B47: ='M. DE CALCULO DE COSTOS VARIABL'!$F$42 -> 22232.811 | C47: ='M. DE CALCULO DE COSTOS VARIABL'!$F$42 -> 22232.811 | D47: ='M. DE CALCULO DE COSTOS VARIABL'!$F$42 -> 22232.811 | E47: ='M. DE CALCULO DE COSTOS VARIABL'!$F$42 -> 22232.811 | F47: ='M. DE CALCULO DE COSTOS VARIABL'!$F$42 -> 22232.811 | G47: ='M. DE CALCULO DE COSTOS VARIABL'!$F$42 -> 22232.811 | H47: ='M. DE CALCULO DE COSTOS VARIABL'!$F$42 -> 22232.811 | I47: ='M. DE CALCULO DE COSTOS VARIABL'!$F$42 -> 22232.811 | ... M47: ='M. DE CALCULO DE COSTOS VARIABL'!$F$42 -> 22232.811 | N47: =SUM(B47:M47) -> 266793.73
A48: TOTAL FIJOS | B48: =B49+B50 -> 33837.194 | C48: =SUM(C49:C50) -> 33837.194 | D48: =SUM(D49:D50) -> 33837.194 | E48: =SUM(E49:E50) -> 33837.194 | F48: =SUM(F49:F50) -> 33837.194 | G48: =SUM(G49:G50) -> 33837.194 | H48: =SUM(H49:H50) -> 33837.194 | I48: =SUM(I49:I50) -> 33837.194 | J48: =SUM(J49:J50) -> 33837.194 | ... M48: =SUM(M49:M50) -> 33837.194 | N48: =SUM(B48:M48) -> 406046.32
...

Sheet M. DE CALCULO DE GASTOS FIJOS
A1: ESTRUCTURA DE INGRESOS Y EGERESOS
A3: MEMORIAS DE CALCULO GASTOS FIJOS
A5: PROYECTO: Las Amarguitas Fabrica de Cervezas y Destilados
A6: SOCIEDAD RESPONSABILIDAD LIMITADA
A7: BENEFICIARIOS: PABLO PUIG TRESS, HUGO PUIG TRESS.
A9: MEMORIA DE CALCULO GASTOS DE ADMINISTRACIÓN | F9: MESES
B10: MEDIDA | C10: CANT | D10: C.U. | E10: TOTAL | F10: 1 | G10: 2 | H10: 3 | I10: 4 | J10: 5 | K10: 6 | L10: 7 | M10: 8 | N10: 9 | O10: 10 | P10: 11 | Q10: 12
A11: Paquete de Internet y telefonía con ADM factura | B11: Servicio | C11: 12 | D11: 320.93 | E11: =D11*C11 -> 3851.16 | F11: =D11 -> 320.93 | G11: =D11 -> 320.93 | H11: =F11 -> 320.93 | I11: =G11 -> 320.93 | J11: =H11 -> 320.93 | K11: =I11 -> 320.93 | L11: =J11 -> 320.93 | M11: =K11 -> 320.93 | N11: =L11 -> 320.93 | O11: =M11 -> 320.93 | ... Q11: =O11 -> 320.93
A12: Gerente General | B12: Meses Trabajados | C12: 12 | D12: =8364.57*2 -> 16729.14 | E12: =D12*C12 -> 200749.68 | F12: =$D$32 -> 16729.14 | G12: =$D$32 -> 16729.14 | H12: =$D$32 -> 16729.14 | I12: =$D$32 -> 16729.14 | J12: =$D$32 -> 16729.14 | K12: =$D$32 -> 16729.14 | L12: =$D$32 -> 16729.14 | M12: =$D$32 -> 16729.14 | ... Q12: =$D$32 -> 16729.14
A13: Subtotal | E13: =SUM(E11:E12) -> 204600.84 | F13: =SUM(F11:F12) -> 17050.07 | G13: =SUM(G11:G12) -> 17050.07 | H13: =SUM(H11:H12) -> 17050.07 | I13: =SUM(I11:I12) -> 17050.07 | J13: =SUM(J11:J12) -> 17050.07 | K13: =SUM(K11:K12) -> 17050.07 | L13: =SUM(L11:L12) -> 17050.07 | ... Q13: =SUM(Q11:Q12) -> 17050.07
A16: MEMORIA DE CALCULO GASTOS DE VENTA | F16: MESES
F17: 1 | G17: 2 | H17: 3 | I17: 4 | J17: 5 | K17: 6 | L17: 7 | M17: 8 | N17: 9 | O17: 10 | P17: 11 | Q17: 12
A18: Gerencia de Ventas | B18: Meses Trabajados | C18: 12 | D18: =7908.32*2 -> 15816.64 | E18: =D18*C18 -> 189799.68 | F18: =D18 -> 15816.64 | G18: =D18 -> 15816.64 | H18: =F18 -> 15816.64 | I18: =G18 -> 15816.64 | J18: =H18 -> 15816.64 | K18: =I18 -> 15816.64 | L18: =J18 -> 15816.64 | M18: =K18 -> 15816.64 | N18: =L18 -> 15816.64 | O18: =M18 -> 15816.64 | ... Q18: =O18 -> 15816.64
A19: Publicidad | B19: tiempo (meses) | C19: 12 | D19: 249.98 | E19: =D19*C19 -> 2999.76 | F19: =$D$39 -> 249.98 | G19: =$D$39 -> 249.98 | H19: =$D$39 -> 249.98 | I19: =$D$39 -> 249.98 | J19: =$D$39 -> 249.98 | K19: =$D$39 -> 249.98 | L19: =$D$39 -> 249.98 | M19: =$D$39 -> 249.98 | ... Q19: =$D$39 -> 249.98
A20: Almacenamiento | B20: tiempo (meses) | C20: 12 | D20: =550.003 -> 550.003 | E20: =D20*C20 -> 6600.036 | F20: =D$40 -> 550.003 | G20: =E$40 -> 6600.036 | H20: =$F$40 -> 550.003 | I20: =$F$40 -> 550.003 | J20: =$F$40 -> 550.003 | K20: =$F$40 -> 550.003 | L20: =$F$40 -> 550.003 | M20: =$F$40 -> 550.003 | N20: =$F$40 -> 550.003 | O20: =$F$40 -> 550.003 | ... Q20: =$F$40 -> 550.003 | R20: =SUM(F41:Q41) -> 205449.51
A21: Subtotal | E21: =SUM(E18:E20) -> 199399.48 | F21: =SUM(F18:F20) -> 16616.623 | G21: =SUM(G18:G20) -> 22666.656 | H21: =SUM(H18:H20) -> 16616.623 | I21: =SUM(I18:I20) -> 16616.623 | J21: =SUM(J18:J20) -> 16616.623 | K21: =SUM(K18:K20) -> 16616.623 | L21: =SUM(L18:L20) -> 16616.623 | ... Q21: =SUM(Q18:Q20) -> 16616.623
A28: MEMORIA DE CALCULO GASTOS DE ADMINISTRACIÓN | F28: MESES
B29: MEDIDA | C29: CANT | D29: C.U. | E29: TOTAL | F29: 1 | G29: 2 | H29: 3 | I29: 4 | J29: 5 | K29: 6 | L29: 7 | M29: 8 | N29: 9 | O29: 10 | P29: 11 | Q29: 12
A30: Paquete de Internet y telefonía con ADM factura | B30: Servicio | C30: 12 | D30: 320.93 | E30: =D30*C30 -> 3851.16 | F30: =D30 -> 320.93 | G30: =D30 -> 320.93 | H30: =F30 -> 320.93 | I30: =G30 -> 320.93 | J30: =H30 -> 320.93 | K30: =I30 -> 320.93 | L30: =J30 -> 320.93 | M30: =K30 -> 320.93 | N30: =L30 -> 320.93 | O30: =M30 -> 320.93 | ... Q30: =O30 -> 320.93
A31: Gerente de Finanzas | B31: Meses Trabajados | C31: 12 | D31: =6083.32*2 -> 12166.64 | E31: =D31*C31 -> 145999.68 | F31: =$D$31 -> 12166.64 | G31: =$D$31 -> 12166.64 | H31: =$D$31 -> 12166.64 | I31: =$D$31 -> 12166.64 | J31: =$D$31 -> 12166.64 | K31: =$D$31 -> 12166.64 | L31: =$D$31 -> 12166.64 | M31: =$D$31 -> 12166.64 | ... Q31: =$D$31 -> 12166.64
A32: Gerente General | B32: Meses Trabajados | C32: 12 | D32: =8364.57*2 -> 16729.14 | E32: =D32*C32 -> 200749.68 | F32: =$D$32 -> 16729.14 | G32: =$D$32 -> 16729.14 | H32: =$D$32 -> 16729.14 | I32: =$D$32 -> 16729.14 | J32: =$D$32 -> 16729.14 | K32: =$D$32 -> 16729.14 | L32: =$D$32 -> 16729.14 | M32: =$D$32 -> 16729.14 | ... Q32: =$D$32 -> 16729.14
A33: Subtotal | E33: =SUM(E30:E32) -> 350600.52 | F33: =SUM(F30:F32) -> 29216.71 | G33: =SUM(G30:G32) -> 29216.71 | H33: =SUM(H30:H32) -> 29216.71 | I33: =SUM(I30:I32) -> 29216.71 | J33: =SUM(J30:J32) -> 29216.71 | K33: =SUM(K30:K32) -> 29216.71 | L33: =SUM(L30:L32) -> 29216.71 | ... Q33: =SUM(Q30:Q32) -> 29216.71
E34: =E32+E30 -> 204600.84
A36: MEMORIA DE CALCULO GASTOS DE VENTA | F36: MESES
F37: 1 | G37: 2 | H37: 3 | I37: 4 | J37: 5 | K37: 6 | L37: 7 | M37: 8 | N37: 9 | O37: 10 | P37: 11 | Q37: 12
A38: Gerencia de Ventas | B38: Meses Trabajados | C38: 12 | D38: =7908.32*2 -> 15816.64 | E38: =D38*C38 -> 189799.68 | F38: =D38 -> 15816.64 | G38: =D38 -> 15816.64 | H38: =F38 -> 15816.64 | I38: =G38 -> 15816.64 | J38: =H38 -> 15816.64 | K38: =I38 -> 15816.64 | L38: =J38 -> 15816.64 | M38: =K38 -> 15816.64 | N38: =L38 -> 15816.64 | O38: =M38 -> 15816.64 | ... Q38: =O38 -> 15816.64
A39: Publicidad | B39: tiempo (meses) | C39: 12 | D39: 249.98 | E39: =D39*C39 -> 2999.76 | F39: =$D$39 -> 249.98 | G39: =$D$39 -> 249.98 | H39: =$D$39 -> 249.98 | I39: =$D$39 -> 249.98 | J39: =$D$39 -> 249.98 | K39: =$D$39 -> 249.98 | L39: =$D$39 -> 249.98 | M39: =$D$39 -> 249.98 | ... Q39: =$D$39 -> 249.98
A40: Almacenamiento | B40: tiempo (meses) | C40: 12 | D40: =550.003 -> 550.003 | E40: =D40*C40 -> 6600.036 | F40: =D$40 -> 550.003 | G40: =E$40 -> 6600.036 | H40: =$F$40 -> 550.003 | I40: =$F$40 -> 550.003 | J40: =$F$40 -> 550.003 | K40: =$F$40 -> 550.003 | L40: =$F$40 -> 550.003 | M40: =$F$40 -> 550.003 | N40: =$F$40 -> 550.003 | O40: =$F$40 -> 550.003 | ... Q40: =$F$40 -> 550.003
A41: Subtotal | E41: =SUM(E38:E40) -> 199399.48 | F41: =SUM(F38:F40) -> 16616.623 | G41: =SUM(G38:G40) -> 22666.656 | H41: =SUM(H38:H40) -> 16616.623 | I41: =SUM(I38:I40) -> 16616.623 | J41: =SUM(J38:J40) -> 16616.623 | K41: =SUM(K38:K40) -> 16616.623 | L41: =SUM(L38:L40) -> 16616.623 | ... Q41: =SUM(Q38:Q40) -> 16616.623
E43: =E41+E33 -> 550000
A45: MEMORIA DE CALCULO GASTOS FIJOS PARA LA INVERSION FIJA | F45: MESES
A46: CONCEPTO | B46: MEDIDA | C46: CANT | D46: C.U. | E46: TOTAL | F46: 1 | G46: 2 | H46: 3 | I46: 4 | J46: 5 | K46: 6 | L46: 7 | M46: 8 | N46: 9 | O46: 10 | P46: 11 | Q46: 12
A47: Gastos de administración | B47: Meses Operados | C47: 12 | E47: =SUM(F47:Q47) -> 350600.52 | F47: =F33 -> 29216.71 | G47: =G33 -> 29216.71 | H47: =H33 -> 29216.71 | I47: =I33 -> 29216.71 | J47: =J33 -> 29216.71 | K47: =K33 -> 29216.71 | L47: =L33 -> 29216.71 | M47: =M33 -> 29216.71 | ... Q47: =Q33 -> 29216.71
A48: gastos de venta | B48: Meses Operados | C48: 12 | E48: =E41 -> 199399.48 | F48: =F41 -> 16616.623 | G48: =G41 -> 22666.656 | H48: =H41 -> 16616.623 | I48: =I41 -> 16616.623 | J48: =J41 -> 16616.623 | K48: =K41 -> 16616.623 | L48: =L41 -> 16616.623 | ... Q48: =Q41 -> 16616.623
A49: TOTAL GASTOS FIJOS | E49: =E47+E48 -> 550000 | F49: =SUM(F47:F48) -> 45833.333 | G49: =SUM(G47:G48) -> 51883.366 | H49: =SUM(H47:H48) -> 45833.333 | I49: =SUM(I47:I48) -> 45833.333 | J49: =SUM(J47:J48) -> 45833.333 | K49: =SUM(K47:K48) -> 45833.333 | L49: =SUM(L47:L48) -> 45833.333 | M49: =SUM(M47:M48) -> 45833.333 | ... Q49: =SUM(Q47:Q48) -> 45833.333

Sheet M. DE CALCULO DE COSTOS VARIABL
A1: ESTRUCTURA DE INGRESOS Y EGERESOS
A3: MEMORIAS DE CALCULO COSTOS VARIABLES
A5: PROYECTO: Las Amarguitas Fabrica de Cervezas y Destilados
A6: SOCIEDAD RESPONSABILIDAD LIMITADA
A7: BENEFICIARIOS: PABLO PUIG TRESS, HUGO PUIG TRESS.
A8: MEMORIA DE CALCULO MATERIA PRIMA E INSUMOS | F8: MEMORIA DE CALCULO MATERIA PRIMA E INSUMOS
A9: Lote 1 (Regia, Golden y Milf) | B9: MEDIDA | C9: CANT | D9: C.U. | E9: TOTAL | G9: MEDIDA | H9: CANT | I9: C.U. | J9: TOTAL
A10: Malta | B10: Kilos | C10: 300 | D10: 25 | E10: =C10*D10 -> 7500 | F10: Lote 2 (Dark, Ver-Got y Honey) | G10: Kilos | H10: 350 | I10: 32 | J10: =H10*I10 -> 11200
A11: Lupulo | B11: Onzas | C11: 200 | D11: 26 | E11: =C11*D11 -> 5200 | F11: Lupulo | G11: Onzas | H11: 250 | I11: 26 | J11: =H11*I11 -> 6500
A12: Levadura | B12: Gramos | C12: 1200 | D12: 4 | E12: =C12*D12 -> 4800 | F12: Levadura | G12: Gramos | H12: 1200 | I12: 4 | J12: =H12*I12 -> 4800
A13: Agua | B13: Litros | C13: 1350 | D13: 0.75 | E13: =C13*D13 -> 1012.5 | F13: Agua | G13: Litros | H13: 1400 | I13: 0.75 | J13: =H13*I13 -> 1050
A14: Cascara de naranja | B14: Kilos | C14: 1.5 | D14: 70 | E14: =C14*D14 -> 105 | F14: Caramelo | G14: Kilos | H14: 30 | I14: 40 | J14: =H14*I14 -> 1200
A15: Cascara de limón | B15: Kilos | C15: 2.25 | D15: 40 | E15: =C15*D15 -> 90 | F15: Durazno (congelado) | G15: Kilos | H15: 130 | I15: 35 | J15: =H15*I15 -> 4550
A16: Especias | B16: Kilos | C16: 5 | D16: 35 | E16: =C16*D16 -> 175 | F16: Pasas | G16: Kilos | H16: 15 | I16: 40 | J16: =H16*I16 -> 600
A17: Gallletas | B17: Kilos | C17: 15 | D17: 32 | E17: =C17*D17 -> 480 | F17: Miel | G17: Kilos | H17: 30 | I17: 50 | J17: =H17*I17 -> 1500
A18: Cafe Tostado | B18: Kilos | C18: 12 | D18: 70 | E18: =C18*D18 -> 840 | F18: Álmivar | G18: litros | H18: 20 | I18: 40 | J18: =I18*H18 -> 800
A19: Cacao Tostado | B19: Kilos | C19: 7.5 | D19: 60 | E19: =C19*D19 -> 450
A20: Almendra | B20: Litros | C20: 1 | D20: 30 | E20: =C20*D20 -> 30
A21: Subtotal | E21: =SUM(E10:E20) -> 20682.5 | F21: Subtotal | J21: =SUM(J10:J20) -> 32200
A24: MEMORIA DE CALCULO DE MOD
A25: Maestro cervecero | B25: Meses Trabajados | C25: 12 | D25: =4562.49*2 -> 9124.98 | E25: =C25*D25 -> 109499.76
A26: Auxiliar de producción | B26: Meses Trabajados | C26: 12 | D26: =3802.08*2 -> 7604.16 | E26: =D26*C26 -> 91249.92 | F26: Total de Materia Prima | G26: =J21+E21 -> 52882.5 | H26: 2 lotes en un mes
A27: Subtotal | D27: =D25+D26 -> 16729.14 | E27: =SUM(E25:E26) -> 200749.68
D29: =D25 -> 9124.98 | E29: =E25 -> 109499.76
A34: MEMORIA DE CALCULO PARA CIF
A35: Energía eléctrica (cálculo mensual de GDMTH) | B35: kWh | C35: 4070 | D35: Variable | E35: 20000 | F35: =E35*1.99 -> 39800
A36: Gas | B36: Litros | C36: 3000 | D36: 10.82 | E36: 23000 | F36: =E36 -> 23000
A37: Material de limpieza | B37: Varios | C37: Variable | D37: =E37 -> 3000 | E37: 3000 | F37: =E37 -> 3000
A38: Material de mantenimiento | B38: Varios | C38: Variable | D38: =E38 -> 6500 | E38: 6500 | F38: =E38 -> 6500
A39: Encargado de matenimiento | B39: Meses Trabajados | C39: 12 | D39: ='CONCENTRADO DE SUELDOS'!O9 -> 10286.211 | E39: =C39*D39 -> 123434.53
A40: Auxiliar de limpieza | B40: Meses Trabajados | C40: 12 | D40: =3785.8*2 -> 7571.6 | E40: =+C40*D40 -> 90859.2 | F40: =E40 -> 90859.2
A41: Subtotal | E41: =SUM(E35:E40) -> 266793.73 | F41: =E41 -> 266793.73
E42: =E41/12 -> 22232.811 | F42: =F41/12 -> 22232.811
A44: =A39 -> Encargado de matenimiento | B44: =B39 -> Meses Trabajados | C44: =C39 -> 12 | D44: ='CONCENTRADO DE SUELDOS'!O9 -> 10286.211 | E44: =C44*D44 -> 123434.53
E45: =E41+E44 -> 390228.25

Sheet DEPRECIACIONES
A1: CALCULO DE DEPRECIACIONES Y AMORTIZACIONES
A3: PROYECTO: Las Amarguitas Fabrica de Cervezas y Destilados
A4: SOCIEDAD RESPONSABILIDAD LIMITADA
A7: MUEBLES Y EQUIPO | B7: VALOR | C7: VIDA UTIL (AÑOS) | D7: TASA DE DEPREC. | E7: DEPRECIACION (ANUAL) | F7: DEPRECIACION (MENSUAL) | G7: DEPRC. ACUM | H7: REMANENTE
A8: Sillas para Escritorios | B8: 12000 | C8: 10 años | D8: 0.1 | E8: =B8*0.1 -> 1200 | F8: =E8/12 -> 100 | G8: =E8*3 -> 3600 | H8: =E8 -> 1200
A9: Escritorios | B9: 30000 | C9: 10 años | D9: 0.1 | E9: =B9*0.1 -> 3000 | F9: =E9/12 -> 250 | G9: =E9*3 -> 9000 | H9: =E9 -> 3000
A10: Computadoras | B10: 30000 | C10: 3-4 años | D10: 0.3 | E10: =B10*0.3 -> 9000 | F10: =E10/12 -> 750 | G10: =E10*3 -> 27000 | H10: =E10 -> 9000
A11: Estantes/Anaqueles | B11: 15000 | C11: 10 años | D11: 0.1 | E11: =B11*0.1 -> 1500 | F11: =E11/12 -> 125 | G11: =E11*3 -> 4500 | H11: =E11 -> 1500
A12: Sillas del restaurante | B12: 35000 | C12: 5 años | D12: 0.2 | E12: =B12*0.2 -> 7000 | F12: =E12/12 -> 583.33333 | G12: =E12*3 -> 21000 | H12: =E12 -> 7000
A13: Mesas del restaurante | B13: 60000 | C13: 5 años | D13: 0.2 | E13: =B13*0.2 -> 12000 | F13: =E13/12 -> 1000 | G13: =E13*3 -> 36000 | H13: =E13 -> 12000
A14: Utencilios de cocina | B14: 9000 | C14: 5 años | D14: 0.2 | E14: =B14*0.2 -> 1800 | F14: =E14/12 -> 150 | G14: =E14*3 -> 5400 | H14: =E14 -> 1800
A15: Vasos | B15: 3000 | C15: 2 años | D15: 0.2 | E15: =B15*0.2 -> 600 | F15: =E15/12 -> 50 | G15: =E15*2 -> 1200 | H15: =E15 -> 600
A16: Copas | B16: 3500 | C16: 2 años | D16: 0.2 | E16: =B16*0.2 -> 700 | F16: =E16/12 -> 58.333333 | G16: =E16*2 -> 1400 | H16: =E16 -> 700
A17: Platos | B17: 2500 | C17: 2 años | D17: 0.2 | E17: =B17*0.2 -> 500 | F17: =E17/12 -> 41.666667 | G17: =E17*2 -> 1000 | H17: =E17 -> 500
A18: Total | B18: =SUM(B8:B17) -> 200000 | E18: =SUM(E8:E17) -> 37300 | F18: =SUM(F8:F17) -> 3108.3333 | H18: =SUM(H8:H17) -> 37300
A21: MAQUINARIA | B21: VALOR | C21: VIDA UTIL (AÑOS) | D21: TASA DE DEPREC. | E21: DEPRECIACION (ANUAL) | F21: DEPRECIACION (MENSUAL) | G21: DEPRC. ACUM | H21: REMANENTE
A22: Plataforma y Escalera de Operación | B22: 50000 | C22: 10 | D22: 0.1 | E22: =B22*D22 -> 5000 | F22: =E22/12 -> 416.66667 | G22: =E22*9 -> 45000 | H22: =B22-G22 -> 5000
A23: Mash Tun / HLT (Tanque de Maceración y Agua Caliente) | B23: 169000 | C23: 10 | D23: 0.1 | E23: =B23*D23 -> 16900 | F23: =E23/12 -> 1408.3333 | G23: =E23*9 -> 152100 | H23: =B23-G23 -> 16900
A24: Lauter Tun (Tanque de Filtración) | B24: 220000 | C24: 10 | D24: 0.1 | E24: =B24*D24 -> 22000 | F24: =E24/12 -> 1833.3333 | G24: =E24*9 -> 198000 | H24: =B24-G24 -> 22000
A25: Kettle / Whirlpool (Tanque de Hervor y Separación) | B25: 50000 | C25: 10 | D25: 0.1 | E25: =B25*D25 -> 5000 | F25: =E25/12 -> 416.66667 | G25: =E25*9 -> 45000 | H25: =B25-G25 -> 5000
A26: Tanque con Agitador y Boquilla para Whirlpool | B26: 125000 | C26: 10 | D26: 0.1 | E26: =B26*D26 -> 12500 | F26: =E26/12 -> 1041.6667 | G26: =E26*9 -> 112500 | H26: =B26-G26 -> 12500
A27: Tanque de Agua Caliente o Fría (HLT/CLT) | B27: 95000 | C27: 10 | D27: 0.1 | E27: =B27*D27 -> 9500 | F27: =E27/12 -> 791.66667 | G27: =E27*9 -> 85500 | H27: =B27-G27 -> 9500
A28: Intercambiador de Calor | B28: 30000 | C28: 10 | D28: 0.1 | E28: =B28*D28 -> 3000 | F28: =E28/12 -> 250 | G28: =E28*9 -> 27000 | H28: =B28-G28 -> 3000
A29: Sistema de Tuberías y Bomba Sanitaria | B29: 20000 | C29: 10 | D29: 0.1 | E29: =B29*D29 -> 2000 | F29: =E29/12 -> 166.66667 | G29: =E29*9 -> 18000 | H29: =B29-G29 -> 2000
B30: =SUM(B22:B29) -> 759000 | H30: =SUM(H22:H29) -> 75900

Sheet AMORTIZACIONES (4 AÑOS)
A1: AMORTIZACIÓN DE LA DEUDA
A3: PROYECTO:
A4: SOCIEDAD
A5: BENEFICIARIOS:
A6: TABLA DE AMORTIZACION DE LA DEUDA
H7: 799000
A8: MESES | B8: TASA DE INTERES | C8: INTERES | D8: DEUDA ACUMULADA | E8: PAGO CAPITAL | F8: PAGO INTERES | G8: PAGO TOTAL | H8: SALDO | I8: FECHAS DE PAGO
A9: 1 | B9: 0.0189 | C9: =H7*B$9 -> 15101.1 | D9: =H7+C9 -> 814101.1 | E9: 16645.83 | F9: =C9 -> 15101.1 | G9: =E9+F9 -> 31746.93 | H9: =D9-G9 -> 782354.17 | I9: =DATE(2025,11,10) -> 45971
A10: 2 | B10: 0.0189 | C10: =H9*B$9 -> 14786.494 | D10: =H9+C10 -> 797140.66 | E10: =E$9 -> 16645.83 | F10: =C10 -> 14786.494 | G10: =E10+F10 -> 31432.324 | H10: =D10-G10 -> 765708.34 | I10: =EDATE(I9,1) -> 46001
A11: 3 | B11: 0.0189 | C11: =H10*B$9 -> 14471.888 | D11: =H10+C11 -> 780180.23 | E11: =E$9 -> 16645.83 | F11: =C11 -> 14471.888 | G11: =E11+F11 -> 31117.718 | H11: =D11-G11 -> 749062.51 | I11: =EDATE(I10,1) -> 46032
A12: 4 | B12: 0.0189 | C12: =H11*B$9 -> 14157.281 | D12: =H11+C12 -> 763219.79 | E12: =E$9 -> 16645.83 | F12: =C12 -> 14157.281 | G12: =E12+F12 -> 30803.111 | H12: =D12-G12 -> 732416.68 | I12: =EDATE(I11,1) -> 46063
A13: 5 | B13: 0.0189 | C13: =H12*B$9 -> 13842.675 | D13: =H12+C13 -> 746259.36 | E13: =E$9 -> 16645.83 | F13: =C13 -> 13842.675 | G13: =E13+F13 -> 30488.505 | H13: =D13-G13 -> 715770.85 | I13: =EDATE(I12,1) -> 46091
A14: 6 | B14: 0.0189 | C14: =H13*B$9 -> 13528.069 | D14: =H13+C14 -> 729298.92 | E14: =E$9 -> 16645.83 | F14: =C14 -> 13528.069 | G14: =E14+F14 -> 30173.899 | H14: =D14-G14 -> 699125.02 | I14: =EDATE(I13,1) -> 46122
A15: 7 | B15: 0.0189 | C15: =H14*B$9 -> 13213.463 | D15: =H14+C15 -> 712338.48 | E15: =E$9 -> 16645.83 | F15: =C15 -> 13213.463 | G15: =E15+F15 -> 29859.293 | H15: =D15-G15 -> 682479.19 | I15: =EDATE(I14,1) -> 46152
A16: 8 | B16: 0.0189 | C16: =H15*B$9 -> 12898.857 | D16: =H15+C16 -> 695378.05 | E16: =E$9 -> 16645.83 | F16: =C16 -> 12898.857 | G16: =E16+F16 -> 29544.687 | H16: =D16-G16 -> 665833.36 | I16: =EDATE(I15,1) -> 46183
A17: 9 | B17: 0.0189 | C17: =H16*B$9 -> 12584.251 | D17: =H16+C17 -> 678417.61 | E17: =E$9 -> 16645.83 | F17: =C17 -> 12584.251 | G17: =E17+F17 -> 29230.081 | H17: =D17-G17 -> 649187.53 | I17: =EDATE(I16,1) -> 46213
A18: 10 | B18: 0.0189 | C18: =H17*B$9 -> 12269.644 | D18: =H17+C18 -> 661457.17 | E18: =E$9 -> 16645.83 | F18: =C18 -> 12269.644 | G18: =E18+F18 -> 28915.474 | H18: =D18-G18 -> 632541.7 | I18: =EDATE(I17,1) -> 46244
A19: 11 | B19: 0.0189 | C19: =H18*B$9 -> 11955.038 | D19: =H18+C19 -> 644496.74 | E19: =E$9 -> 16645.83 | F19: =C19 -> 11955.038 | G19: =E19+F19 -> 28600.868 | H19: =D19-G19 -> 615895.87 | I19: =EDATE(I18,1) -> 46275
A20: 12 | B20: 0.0189 | C20: =H19*B$9 -> 11640.432 | D20: =H19+C20 -> 627536.3 | E20: =E$9 -> 16645.83 | F20: =C20 -> 11640.432 | G20: =E20+F20 -> 28286.262 | H20: =D20-G20 -> 599250.04 | I20: =EDATE(I19,1) -> 46305
A21: 13 | B21: 0.0189 | C21: =H20*B$9 -> 11325.826 | D21: =H20+C21 -> 610575.87 | E21: =E$9 -> 16645.83 | F21: =C21 -> 11325.826 | G21: =E21+F21 -> 27971.656 | H21: =D21-G21 -> 582604.21 | I21: =EDATE(I20,1) -> 46336
... A43: 35 | B43: 0.0189 | C43: =H42*B$9 -> 4404.4896 | D43: =H42+C43 -> 237446.27 | E43: =E$9 -> 16645.83 | F43: =C43 -> 4404.4896 | G43: =E43+F43 -> 21050.32 | H43: =D43-G43 -> 216395.95 | I43: =EDATE(I42,1) -> 47006
A44: 36 | B44: 0.0189 | C44: =H43*B$9 -> 4089.8835 | D44: =H43+C44 -> 220485.83 | E44: =E$9 -> 16645.83 | F44: =C44 -> 4089.8835 | G44: =E44+F44 -> 20735.713 | H44: =D44-G44 -> 199750.12
A45: 37 | B45: 0.0189 | C45: =H44*B$9 -> 3775.2773 | D45: =H44+C45 -> 203525.4 | E45: =E$9 -> 16645.83 | F45: =C45 -> 3775.2773 | G45: =E45+F45 -> 20421.107 | H45: =D45-G45 -> 183104.29
A46: 38 | B46: 0.0189 | C46: =H45*B$9 -> 3460.6711 | D46: =H45+C46 -> 186564.96 | E46: =E$9 -> 16645.83 | F46: =C46 -> 3460.6711 | G46: =E46+F46 -> 20106.501 | H46: =D46-G46 -> 166458.46
A47: 39 | B47: 0.0189 | C47: =H46*B$9 -> 3146.0649 | D47: =H46+C47 -> 169604.52 | E47: =E$9 -> 16645.83 | F47: =C47 -> 3146.0649 | G47: =E47+F47 -> 19791.895 | H47: =D47-G47 -> 149812.63
A48: 40 | B48: 0.0189 | C48: =H47*B$9 -> 2831.4587 | D48: =H47+C48 -> 152644.09 | E48: =E$9 -> 16645.83 | F48: =C48 -> 2831.4587 | G48: =E48+F48 -> 19477.289 | H48: =D48-G48 -> 133166.8 | K48: CALCULO POR MES
A49: 41 | B49: 0.0189 | C49: =H48*B$9 -> 2516.8525 | D49: =H48+C49 -> 135683.65 | E49: =E$9 -> 16645.83 | F49: =C49 -> 2516.8525 | G49: =E49+F49 -> 19162.683 | H49: =D49-G49 -> 116520.97
A50: 42 | B50: 0.0189 | C50: =H49*B$9 -> 2202.2463 | D50: =H49+C50 -> 118723.22 | E50: =E$9 -> 16645.83 | F50: =C50 -> 2202.2463 | G50: =E50+F50 -> 18848.076 | H50: =D50-G50 -> 99875.14
A51: 43 | B51: 0.0189 | C51: =H50*B$9 -> 1887.6401 | D51: =H50+C51 -> 101762.78 | E51: =E$9 -> 16645.83 | F51: =C51 -> 1887.6401 | G51: =E51+F51 -> 18533.47 | H51: =D51-G51 -> 83229.31
A52: 44 | B52: 0.0189 | C52: =H51*B$9 -> 1573.034 | D52: =H51+C52 -> 84802.344 | E52: =E$9 -> 16645.83 | F52: =C52 -> 1573.034 | G52: =E52+F52 -> 18218.864 | H52: =D52-G52 -> 66583.48
A53: 45 | B53: 0.0189 | C53: =H52*B$9 -> 1258.4278 | D53: =H52+C53 -> 67841.908 | E53: =E$9 -> 16645.83 | F53: =C53 -> 1258.4278 | G53: =E53+F53 -> 17904.258 | H53: =D53-G53 -> 49937.65
A54: 46 | B54: 0.0189 | C54: =H53*B$9 -> 943.82159 | D54: =H53+C54 -> 50881.472 | E54: =E$9 -> 16645.83 | F54: =C54 -> 943.82159 | G54: =E54+F54 -> 17589.652 | H54: =D54-G54 -> 33291.82
A55: 47 | B55: 0.0189 | C55: =H54*B$9 -> 629.2154 | D55: =H54+C55 -> 33921.035 | E55: =E$9 -> 16645.83 | F55: =C55 -> 629.2154 | G55: =E55+F55 -> 17275.045 | H55: =D55-G55 -> 16645.99
A56: 48 | B56: 0.0189 | C56: =H55*B$9 -> 314.60921 | D56: =H55+C56 -> 16960.599 | E56: =E$9 -> 16645.83 | F56: =C56 -> 314.60921 | G56: =E56+F56 -> 16960.439 | H56: =D56-G56 -> 0.16
A58: TOTAL
C59: =SUM(C9:C12) -> 58516.763 | D59: =D43 -> 237446.27 | E59: =SUM(E9:E43) -> 582604.05 | F59: =SUM(F9:F43) -> 341347.82 | G59: =SUM(E59:F59) -> 923951.87
A63: PRIMERA MINISTRACIÓN
A64: MONTO: | F64: SE
A65: FECHA: | F65: tiempo | G65: 4 | H65: =G65*12 -> 48
A66: SEGUNDA MINISTRACIÓN | F66: tasa anual | G66: 0.227 | H66: Frecuencia | I66: 48
...

Sheet PROYECCIONES EGRESOS E INGRESOS
A4: 4.9 PUNTO DE EQUILIBRIO
A5: CONCEPTO | B5: AÑO 1 | C5: AÑO 2 | D5: AÑO 3 | E5: AÑO 4 | F5: AÑO 5 | S5: PRECIO UNITARIO | T5: 97.5
A6: INGRESOS | S6: COSTO VARIABLE UNITARIO | T6: =B10/(2990*12) -> 48.226798
A7: VENTAS | B7: ='CUADRO DE EGRESOS E INGRESOS'!O13 -> 3655699 | C7: =INGRESOS!N29 -> 4156302.4 | D7: =INGRESOS!N41 -> 4530369.6 | E7: =INGRESOS!N53 -> 4938102.9 | F7: =INGRESOS!N65 -> 5382532.2 | S7: COSTO FIJO TOTAL | T7: 669999.96 | U7: =T20*15% -> #REF!
A9: COSTOS DE OPERACION | S9: PUNTO DE EQUILIBRIO UNITARIO | T9: =T7/(T5-T6) -> 13597.654
A10: COSTOS VARIABLES | B10: =COSTOS!N29 -> 1730377.5 | C10: =COSTOS!N44 -> 1741856.3 | D10: =COSTOS!N57 -> 1753426.1 | E10: =COSTOS!N70 -> 1765087.8 | F10: =COSTOS!N83 -> 1776842.1 | S10: PUNTO DE EQUILIBRIO UNITARIO | T10: =T7/(1-(T6/T5)) -> 1325771.3
A11: COSTOS FIJOS | B11: =COSTOS!N33 -> 404000.32 | C11: =COSTOS!N48 -> 406046.32 | D11: =COSTOS!N61 -> 408112.79 | E11: =COSTOS!N74 -> 410199.93 | F11: =COSTOS!N87 -> 412307.93
A13: UTILIDAD DE OPERACIÓN | B13: =B7-B10-B11 -> 1521321.2 | C13: =C7-C10-C11 -> 2008399.8 | D13: =D7-D10-D11 -> 2368830.7 | E13: =E7-E10-E11 -> 2762815.2 | F13: =F7-F10-F11 -> 3193382.1
A14: IMPUESTOS | B14: ='CUADRO DE EGRESOS E INGRESOS'!Q17 -> 598528.49 | C14: ='CUADRO DE EGRESOS E INGRESOS'!Q31 -> 793359.94 | D14: ='CUADRO DE EGRESOS E INGRESOS'!Q44 -> 937532.29 | E14: ='CUADRO DE EGRESOS E INGRESOS'!Q55 -> 1095960.9 | F14: ='CUADRO DE EGRESOS E INGRESOS'!Q67 -> 1267352.9
A15: PAGO CAPITAL | B15: ='AMORTIZACIONES (4 AÑOS)'!E12*12 -> 199749.96 | C15: =SUM('AMORTIZACIONES (4 AÑOS)'!E21:E32) -> 199749.96 | D15: =SUM('AMORTIZACIONES (4 AÑOS)'!E33:E44) -> 199749.96 | E15: =SUM('AMORTIZACIONES (4 AÑOS)'!E45:E56) -> 199749.96 | F15: 0
A16: UTILIDAD NETA | B16: =B13-B14-B15 -> 723042.77 | C16: =C13-C14-C15 -> 1015289.9 | D16: =D13-D14-D15 -> 1231548.5 | E16: =E13-E14-E15 -> 1467104.3 | F16: =F13-F14-F15 -> 1926029.3
A17: PUNTO DE EQUILIBRIO
A18: como % de ventas
T19: =T20/T26 -> #REF!
S20: ventas | T20: =#REF! -> #REF! | U20: =#REF!*1.2 -> #REF! | V20: =#REF!*1.3 -> #REF! | W20: =T20/T5 -> #REF!
S21: costo variable | T21: =T19*T6 -> #REF! | U21: =COSTOS!N29*1.2 -> 2076453 | V21: =COSTOS!N29*1.3 -> 2249490.8 | W21: =T6*W20 -> #REF!
A22: UTILIDAD POR SOCIO | B22: =+B16/30 -> 24101.426 | C22: =+C16/30 -> 33842.998 | D22: =+D16/30 -> 41051.616 | E22: =+E16/30 -> 48903.476 | F22: =+F16/30 -> 64200.976 | S22: costos fijos | T22: =U7 -> #REF! | U22: =COSTOS!N33*1.2 -> 484800.38 | V22: =COSTOS!N33*1.3 -> 525200.41
W24: UNIDADES MONETARIAS
A25: GRÁFICA DEL PUNTO DE EQUILIBRIO | S25: COSTO FIJO | T25: ='M. DE CALCULO DE GASTOS FIJOS'!E43 -> 550000 | W25: PEu | X25: CF
S26: PRECIO DE VENTA - UNITARIO (Pvu) | T26: =T5 -> 97.5 | X26: 1- Cvu
S27: COSTO VARIAB. - UNIT (Cvu) | T27: =T6 -> 48.226798 | X27: PVU
S28: P.E UNIDADES MONT | T28: =$T$25/(1-$T$27/$T$26) -> 1088319.8
W30: UNIDADES PRODUCIDAS
S31: COSTO FIJO | T31: =T25 -> 550000
S32: PRECIO DE VENTA - UNITARIO (Pvu) | T32: =T26 -> 97.5
S33: COSTO VARIAB. - UNIT (Cvu) | T33: =T27 -> 48.226798
S34: P.E UNIDADES PROD | T34: =$T$31/($T$32-$T$33) -> 11162.254 | U34: 30000
S35: UTILIDAD | T35: =($T$32*U34)-($T$33*U34)-T31 -> 928196.07
T37: CANTIDAD | U37: VENTAS | V37: COSTOS TOTALES | W37: UTILIDADES
T38: =T39-4283 -> 6879.254 | U38: =$T$32*T38 -> 670727.26 | V38: =$T$31+$T$33*T38 -> 881764.39 | W38: =U38-V38 -> -211037.12
T39: =T34 -> 11162.254 | U39: =$T$32*T39 -> 1088319.8 | V39: =$T$31+$T$33*T39 -> 1088319.8 | W39: =U39-V39 -> 0
T40: =T39+4283 -> 15445.254 | U40: =$T$32*T40 -> 1505912.3 | V40: =$T$31+$T$33*T40 -> 1294875.1 | W40: =U40-V40 -> 211037.12
T41: =T40+4283 -> 19728.254 | U41: =$T$32*T41 -> 1923504.8 | V41: =$T$31+$T$33*T41 -> 1501430.5 | W41: =U41-V41 -> 422074.25
T42: =T41+4283 -> 24011.254 | U42: =$T$32*T42 -> 2341097.3 | V42: =$T$31+$T$33*T42 -> 1707985.9 | W42: =U42-V42 -> 633111.37
T43: =T42+4283 -> 28294.254 | U43: =$T$32*T43 -> 2758689.8 | V43: =$T$31+$T$33*T43 -> 1914541.3 | W43: =U43-V43 -> 844148.5
T44: =T43+4283 -> 32577.254 | U44: =$T$32*T44 -> 3176282.3 | V44: =$T$31+$T$33*T44 -> 2121096.6 | W44: =U44-V44 -> 1055185.6
T45: =T44+4283 -> 36860.254 | U45: =$T$32*T45 -> 3593874.8 | V45: =$T$31+$T$33*T45 -> 2327652 | W45: =U45-V45 -> 1266222.7

Sheet SENSIBILIDAD
A1: SENSIBILIZACION
A3: PROYECTO:
A4: SOCIEDAD
A5: BENEFICIARIOS:
A6: PARA EL PRIMER AÑO
C7: CAMBIO EN VENTAS | G7: CAMBIO EN COSTOS
A8: CONCEPTO | B8: TOTAL PROYECTO | C8: 0.05 | D8: 0.1 | E8: 0.15 | F8: 0.2 | G8: 0.05 | H8: 0.1 | I8: 0.15 | J8: 0.2
A9: VENTAS | B9: ='PROYECCIONES EGRESOS E INGRESOS'!$B$7 -> 3655699 | C9: ='PROYECCIONES EGRESOS E INGRESOS'!$B$7*1.05 -> 3838484 | D9: ='PROYECCIONES EGRESOS E INGRESOS'!$B$7*1.1 -> 4021269 | E9: ='PROYECCIONES EGRESOS E INGRESOS'!$B$7*1.15 -> 4204053.9 | F9: ='PROYECCIONES EGRESOS E INGRESOS'!$B$7*1.2 -> 4386838.9 | G9: ='PROYECCIONES EGRESOS E INGRESOS'!$B$7 -> 3655699 | H9: ='PROYECCIONES EGRESOS E INGRESOS'!$B$7 -> 3655699 | I9: ='PROYECCIONES EGRESOS E INGRESOS'!$B$7 -> 3655699 | J9: ='PROYECCIONES EGRESOS E INGRESOS'!$B$7 -> 3655699
A10: COSTOS TOTALES | B10: ='PROYECCIONES EGRESOS E INGRESOS'!$B$10+'PROYECCIONES EGRESOS E INGRESOS'!$B$11 -> 2134377.8 | C10: ='PROYECCIONES EGRESOS E INGRESOS'!$B$10+'PROYECCIONES EGRESOS E INGRESOS'!$B$11 -> 2134377.8 | D10: ='PROYECCIONES EGRESOS E INGRESOS'!$B$10+'PROYECCIONES EGRESOS E INGRESOS'!$B$11 -> 2134377.8 | E10: ='PROYECCIONES EGRESOS E INGRESOS'!$B$10+'PROYECCIONES EGRESOS E INGRESOS'!$B$11 -> 2134377.8 | F10: ='PROYECCIONES EGRESOS E INGRESOS'!$B$10+'PROYECCIONES EGRESOS E INGRESOS'!$B$11 -> 2134377.8 | G10: ='PROYECCIONES EGRESOS E INGRESOS'!$B$10+'PROYECCIONES EGRESOS E INGRESOS'!$B$11*1.05 -> 2154577.8 | H10: ='PROYECCIONES EGRESOS E INGRESOS'!$B$10+'PROYECCIONES EGRESOS E INGRESOS'!$B$11*1.1 -> 2174777.9 | I10: ='PROYECCIONES EGRESOS E INGRESOS'!$B$10+'PROYECCIONES EGRESOS E INGRESOS'!$B$11*1.15 -> 2194977.9 | J10: ='PROYECCIONES EGRESOS E INGRESOS'!$B$10+'PROYECCIONES EGRESOS E INGRESOS'!$B$11*1.2 -> 2215177.9
A11: TOTAL | B11: =SUM(B9-B10) -> 1521321.2 | C11: =C9-C10 -> 1704106.2 | D11: =D9-D10 -> 1886891.1 | E11: =E9-E10 -> 2069676.1 | F11: =F9-F10 -> 2252461 | G11: =G9-G10 -> 1501121.2 | H11: =H9-H10 -> 1480921.2 | I11: =I9-I10 -> 1460721.2 | J11: =J9-J10 -> 1440521.2
A13: RELACION B/C | B13: =+B9/B10 -> 1.7127703 | C13: =+C9/C10 -> 1.7984089 | D13: =+D9/D10 -> 1.8840474 | E13: =+E9/E10 -> 1.9696859 | F13: =+F9/F10 -> 2.0553244 | G13: =+G9/G10 -> 1.6967125 | H13: =+H9/H10 -> 1.6809529 | I13: =+I9/I10 -> 1.6654833 | J13: =+J9/J10 -> 1.6502959
A15: PARA EL SEGUNDO AÑO
C16: CAMBIO EN VENTAS | G16: CAMBIO EN COSTOS
A17: CONCEPTO | B17: TOTAL PROYECTO | C17: 0.05 | D17: 0.1 | E17: 0.15 | F17: 0.2 | G17: 0.05 | H17: 0.1 | I17: 0.15 | J17: 0.2
A18: VENTAS | B18: ='PROYECCIONES EGRESOS E INGRESOS'!$C$7 -> 4156302.4 | C18: ='PROYECCIONES EGRESOS E INGRESOS'!$C$7*1.05 -> 4364117.5 | D18: ='PROYECCIONES EGRESOS E INGRESOS'!$C$7*1.1 -> 4571932.7 | E18: ='PROYECCIONES EGRESOS E INGRESOS'!$C$7*1.15 -> 4779747.8 | F18: ='PROYECCIONES EGRESOS E INGRESOS'!$C$7*1.2 -> 4987562.9 | G18: ='PROYECCIONES EGRESOS E INGRESOS'!$C$7 -> 4156302.4 | H18: ='PROYECCIONES EGRESOS E INGRESOS'!$C$7 -> 4156302.4 | I18: ='PROYECCIONES EGRESOS E INGRESOS'!$C$7 -> 4156302.4 | J18: ='PROYECCIONES EGRESOS E INGRESOS'!$C$7 -> 4156302.4
A19: COSTOS TOTALES | B19: ='PROYECCIONES EGRESOS E INGRESOS'!C14+'PROYECCIONES EGRESOS E INGRESOS'!$C$15 -> 993109.9 | C19: =$B$19 -> 993109.9 | D19: =$B$19 -> 993109.9 | E19: =$B$19 -> 993109.9 | F19: =$B$19 -> 993109.9 | G19: =$B$19*1.05 -> 1042765.4 | H19: =$B$19*1.1 -> 1092420.9 | I19: =$B$19*1.15 -> 1142076.4 | J19: =$B$19*1.2 -> 1191731.9
A20: TOTAL | B20: =SUM(B18-B19) -> 3163192.5 | C20: =C18-C19 -> 3371007.7 | D20: =D18-D19 -> 3578822.8 | E20: =E18-E19 -> 3786637.9 | F20: =F18-F19 -> 3994453 | G20: =G18-G19 -> 3113537 | H20: =H18-H19 -> 3063881.5 | I20: =I18-I19 -> 3014226 | J20: =J18-J19 -> 2964570.6
A22: RELACION B/C | B22: =+B18/B19 -> 4.1851385 | C22: =+C18/C19 -> 4.3943954 | D22: =+D18/D19 -> 4.6036523 | E22: =+E18/E19 -> 4.8129092 | F22: =+F18/F19 -> 5.0221662 | G22: =+G18/G19 -> 3.9858462 | H22: =+H18/H19 -> 3.8046713 | I22: =+I18/I19 -> 3.6392508 | J22: =+J18/J19 -> 3.4876154
A25: PARA EL TERCER AÑO
C26: CAMBIO EN VENTAS | G26: CAMBIO EN COSTOS
A27: CONCEPTO | B27: TOTAL PROYECTO | C27: 0.05 | D27: 0.1 | E27: 0.15 | F27: 0.2 | G27: 0.05 | H27: 0.1 | I27: 0.15 | J27: 0.2
A28: VENTAS | B28: ='PROYECCIONES EGRESOS E INGRESOS'!$D$7 -> 4530369.6 | C28: ='PROYECCIONES EGRESOS E INGRESOS'!$D$7*1.05 -> 4756888.1 | D28: ='PROYECCIONES EGRESOS E INGRESOS'!$D$7*1.1 -> 4983406.6 | E28: ='PROYECCIONES EGRESOS E INGRESOS'!$D$7*1.15 -> 5209925.1 | F28: ='PROYECCIONES EGRESOS E INGRESOS'!$D$7*1.2 -> 5436443.6 | G28: ='PROYECCIONES EGRESOS E INGRESOS'!$D$7 -> 4530369.6 | H28: ='PROYECCIONES EGRESOS E INGRESOS'!$D$7 -> 4530369.6 | I28: ='PROYECCIONES EGRESOS E INGRESOS'!$D$7 -> 4530369.6 | J28: ='PROYECCIONES EGRESOS E INGRESOS'!$D$7 -> 4530369.6
A29: COSTOS TOTALES | B29: ='PROYECCIONES EGRESOS E INGRESOS'!$D$10+'PROYECCIONES EGRESOS E INGRESOS'!$D$11 -> 2161538.9 | C29: ='PROYECCIONES EGRESOS E INGRESOS'!$D$10+'PROYECCIONES EGRESOS E INGRESOS'!$D$11 -> 2161538.9 | D29: ='PROYECCIONES EGRESOS E INGRESOS'!$D$10+'PROYECCIONES EGRESOS E INGRESOS'!$D$11 -> 2161538.9 | E29: ='PROYECCIONES EGRESOS E INGRESOS'!$D$10+'PROYECCIONES EGRESOS E INGRESOS'!$D$11 -> 2161538.9 | F29: ='PROYECCIONES EGRESOS E INGRESOS'!$D$10+'PROYECCIONES EGRESOS E INGRESOS'!$D$11 -> 2161538.9 | G29: =('PROYECCIONES EGRESOS E INGRESOS'!$D$10+'PROYECCIONES EGRESOS E INGRESOS'!$D$11)*1.05 -> 2269615.9 | H29: =('PROYECCIONES EGRESOS E INGRESOS'!$D$10+'PROYECCIONES EGRESOS E INGRESOS'!$D$11)*1.1 -> 2377692.8 | I29: =('PROYECCIONES EGRESOS E INGRESOS'!$D$10+'PROYECCIONES EGRESOS E INGRESOS'!$D$11)*1.15 -> 2485769.8 | J29: =('PROYECCIONES EGRESOS E INGRESOS'!$D$10+'PROYECCIONES EGRESOS E INGRESOS'!$D$11)*1.2 -> 2593846.7
A30: TOTAL | B30: =SUM(B28-B29) -> 2368830.7 | C30: =C28-C29 -> 2595349.2 | D30: =D28-D29 -> 2821867.7 | E30: =E28-E29 -> 3048386.2 | F30: =F28-F29 -> 3274904.7 | G30: =G28-G29 -> 2260753.8 | H30: =H28-H29 -> 2152676.8 | I30: =I28-I29 -> 2044599.9 | J30: =J28-J29 -> 1936522.9
A32: RELACION B/C | B32: =+B28/B29 -> 2.0959001 | C32: =+C28/C29 -> 2.2006951 | D32: =+D28/D29 -> 2.3054901 | E32: =+E28/E29 -> 2.4102851 | F32: =+F28/F29 -> 2.5150801 | G32: =+G28/G29 -> 1.9960953 | H32: =+H28/H29 -> 1.9053637 | I32: =+I28/I29 -> 1.8225218 | J32: =+J28/J29 -> 1.7465834
A36: PARA EL CUARTO AÑO
C37: CAMBIO EN VENTAS | G37: CAMBIO EN COSTOS
A38: CONCEPTO | B38: TOTAL PROYECTO | C38: 0.05 | D38: 0.1 | E38: 0.15 | F38: 0.2 | G38: 0.05 | H38: 0.1 | I38: 0.15 | J38: 0.2
A39: VENTAS | B39: ='PROYECCIONES EGRESOS E INGRESOS'!$E$7 -> 4938102.9 | C39: ='PROYECCIONES EGRESOS E INGRESOS'!$E$7 -> 4938102.9 | D39: ='PROYECCIONES EGRESOS E INGRESOS'!$E$7 -> 4938102.9 | E39: ='PROYECCIONES EGRESOS E INGRESOS'!$E$7 -> 4938102.9 | F39: ='PROYECCIONES EGRESOS E INGRESOS'!$E$7 -> 4938102.9 | G39: ='PROYECCIONES EGRESOS E INGRESOS'!$E$7 -> 4938102.9 | H39: ='PROYECCIONES EGRESOS E INGRESOS'!$E$7 -> 4938102.9 | I39: ='PROYECCIONES EGRESOS E INGRESOS'!$E$7 -> 4938102.9 | J39: ='PROYECCIONES EGRESOS E INGRESOS'!$E$7 -> 4938102.9
A40: COSTOS TOTALES | B40: ='PROYECCIONES EGRESOS E INGRESOS'!$E$10+'PROYECCIONES EGRESOS E INGRESOS'!$E$11 -> 2175287.8 | C40: ='PROYECCIONES EGRESOS E INGRESOS'!$E$10+'PROYECCIONES EGRESOS E INGRESOS'!$E$11 -> 2175287.8 | D40: ='PROYECCIONES EGRESOS E INGRESOS'!$E$10+'PROYECCIONES EGRESOS E INGRESOS'!$E$11 -> 2175287.8 | E40: ='PROYECCIONES EGRESOS E INGRESOS'!$E$10+'PROYECCIONES EGRESOS E INGRESOS'!$E$11 -> 2175287.8 | F40: ='PROYECCIONES EGRESOS E INGRESOS'!$E$10+'PROYECCIONES EGRESOS E INGRESOS'!$E$11 -> 2175287.8 | G40: =('PROYECCIONES EGRESOS E INGRESOS'!$E$10+'PROYECCIONES EGRESOS E INGRESOS'!$E$11)*1.05 -> 2284052.1 | H40: =('PROYECCIONES EGRESOS E INGRESOS'!$E$10+'PROYECCIONES EGRESOS E INGRESOS'!$E$11)*1.1 -> 2392816.5 | I40: =('PROYECCIONES EGRESOS E INGRESOS'!$E$10+'PROYECCIONES EGRESOS E INGRESOS'!$E$11)*1.15 -> 2501580.9 | J40: =('PROYECCIONES EGRESOS E INGRESOS'!$E$10+'PROYECCIONES EGRESOS E INGRESOS'!$E$11)*1.2 -> 2610345.3
A41: TOTAL | B41: =B39-B40 -> 2762815.2 | C41: =C39-C40 -> 2762815.2 | D41: =D39-D40 -> 2762815.2 | E41: =E39-E40 -> 2762815.2 | F41: =F39-F40 -> 2762815.2 | G41: =G39-G40 -> 2654050.8 | H41: =H39-H40 -> 2545286.4 | I41: =I39-I40 -> 2436522 | J41: =J39-J40 -> 2327757.6
A43: RELACION B/C | B43: =+B39/B40 -> 2.2700918 | C43: =+C39/C40 -> 2.2700918 | D43: =+D39/D40 -> 2.2700918 | E43: =+E39/E40 -> 2.2700918 | F43: =+F39/F40 -> 2.2700918 | G43: =+G39/G40 -> 2.1619922 | H43: =+H39/H40 -> 2.0637198 | I43: =+I39/I40 -> 1.9739929 | J43: =+J39/J40 -> 1.8917432
A47: PARA EL QUINTO AÑO
C48: CAMBIO EN VENTAS | G48: CAMBIO EN COSTOS
A49: CONCEPTO | B49: TOTAL PROYECTO | C49: 0.05 | D49: 0.1 | E49: 0.15 | F49: 0.2 | G49: 0.05 | H49: 0.1 | I49: 0.15 | J49: 0.2
A50: VENTAS | B50: ='PROYECCIONES EGRESOS E INGRESOS'!$F$7 -> 5382532.2 | C50: ='PROYECCIONES EGRESOS E INGRESOS'!$F$7 -> 5382532.2 | D50: ='PROYECCIONES EGRESOS E INGRESOS'!$F$7 -> 5382532.2 | E50: ='PROYECCIONES EGRESOS E INGRESOS'!$F$7 -> 5382532.2 | F50: ='PROYECCIONES EGRESOS E INGRESOS'!$F$7 -> 5382532.2 | G50: ='PROYECCIONES EGRESOS E INGRESOS'!$F$7 -> 5382532.2 | H50: ='PROYECCIONES EGRESOS E INGRESOS'!$F$7 -> 5382532.2 | I50: ='PROYECCIONES EGRESOS E INGRESOS'!$F$7 -> 5382532.2 | J50: ='PROYECCIONES EGRESOS E INGRESOS'!$F$7 -> 5382532.2
A51: COSTOS TOTALES | B51: ='PROYECCIONES EGRESOS E INGRESOS'!$F$10+'PROYECCIONES EGRESOS E INGRESOS'!$F$11 -> 2189150 | C51: ='PROYECCIONES EGRESOS E INGRESOS'!$F$10+'PROYECCIONES EGRESOS E INGRESOS'!$F$11 -> 2189150 | D51: ='PROYECCIONES EGRESOS E INGRESOS'!$F$10+'PROYECCIONES EGRESOS E INGRESOS'!$F$11 -> 2189150 | E51: ='PROYECCIONES EGRESOS E INGRESOS'!$F$10+'PROYECCIONES EGRESOS E INGRESOS'!$F$11 -> 2189150 | F51: ='PROYECCIONES EGRESOS E INGRESOS'!$F$10+'PROYECCIONES EGRESOS E INGRESOS'!$F$11 -> 2189150 | G51: =('PROYECCIONES EGRESOS E INGRESOS'!$F$10+'PROYECCIONES EGRESOS E INGRESOS'!$F$11)*1.1 -> 2408065 | H51: =('PROYECCIONES EGRESOS E INGRESOS'!$F$10+'PROYECCIONES EGRESOS E INGRESOS'!$F$11)*1.1 -> 2408065 | I51: =('PROYECCIONES EGRESOS E INGRESOS'!$F$10+'PROYECCIONES EGRESOS E INGRESOS'!$F$11)*1.15 -> 2517522.6 | J51: =('PROYECCIONES EGRESOS E INGRESOS'!$F$10+'PROYECCIONES EGRESOS E INGRESOS'!$F$11)*1.2 -> 2626980.1
A52: TOTAL | B52: =B50-B51 -> 3193382.1 | C52: =C50-C51 -> 3193382.1 | D52: =D50-D51 -> 3193382.1 | E52: =E50-E51 -> 3193382.1 | F52: =F50-F51 -> 3193382.1 | G52: =G50-G51 -> 2974467.1 | H52: =H50-H51 -> 2974467.1 | I52: =I50-I51 -> 2865009.6 | J52: =J50-J51 -> 2755552.1
